Workbook
Name NativeTimeline_Date: #N/A
Name Slicer_month: #N/A
Name Slicer_Payment_Method: #N/A
Name Slicer_Region: #N/A

Sheet INSIGHTS & STORYTELLING
A1: Final Report: Sales Performance & Customer Insights
A3: 1. Executive Summary
A5: The report analyzes sales trends, customer behavior, and product performance.
A7: Objective: Identify high-value customers, most purchased products, and overall business performance for informed decision-making.
A9: Tools used: Excel (Pivot Tables, Charts, Slicers, Conditional Formatting, SUMIFS, Date/Time functions, Timeline).
A13: 2. Data Overview
A15: Dataset contains transaction details: customer names, product names, purchase date, payment method, quantity, and amount.
A17: Data preparation steps:
A21: Extracted month and year for time-based analysis using MONTH() and YEAR().
A23: Created helper columns for abbreviations and comparison between lists.
A25: Checked data quality: removed blanks, formatted amounts, ensured numeric values in totals.
A29: 3. Sales Performance
... A147: Helper columns for month, abbreviations, and comparisons.

Sheet SALES DASHBOARD

Sheet RAW DATA
A1: Transaction_ID | B1: Date | C1: month | D1: Customer_ID | E1: Customer_Name | F1: Product_ID | G1: Product_Name | H1: Category | I1: Quantity | J1: Unit_Price | K1: Payment_Method | L1: Region | M1: Customer_Segment | N1: Customer_Since | O1: Total_Amount | P1: customer tenure | Q1: highvalue | R1: product_count | S1: total sales | T1: intials
A2: TRX0155 | B2: 45393 | C2: =TEXT(B2,"mmmm") -> April | D2: CUST023 | E2: Paul Baker | F2: P009 | G2: Monitor | H2: Electronics | I2: 5 | J2: 274.98 | K2: Cash | L2: Central | M2: Basic | N2: 44425 | O2: 749.97 | P2: =DATEDIF(O2,TODAY(),"Y") -> 124 | Q2: =IF(O2>2000,"High Value","Normal") -> Normal | R2: =COUNTIF(G:G,G2) -> 26 | S2: =SUM(O2:O251) -> 229192.47 | T2: =LEFT(E2,1)&MID(E2,FIND(" ",E2)+1,1) -> PB
A3: TRX0023 | B3: 45396 | C3: =TEXT(B3,"mmmm") -> April | D3: CUST013 | E3: Joseph Jackson | F3: P009 | G3: Monitor | H3: Electronics | I3: 0 | J3: 249.99 | K3: Credit Card | L3: Central | M3: Premium | N3: 44575 | O3: 749.97 | P3: =DATEDIF(O3,TODAY(),"Y") -> 124 | Q3: =IF(O3>2000,"High Value","Normal") -> Normal | R3: =COUNTIF(G:G,G3) -> 26 | S3: average | T3: =LEFT(E3,1)&MID(E3,FIND(" ",E3)+1,1) -> JJ
A4: TRX0139 | B4: 45399 | C4: =TEXT(B4,"mmmm") -> April | D4: CUST021 | E4: Kevin Scott | F4: P005 | G4: Blender | H4: Appliances | I4: 30 | J4: 59.99 | K4: PayPal | L4: South | M4: Standard | N4: 45262 | O4: 179.97 | P4: =DATEDIF(O4,TODAY(),"Y") -> 125 | Q4: =IF(O4>2000,"High Value","Normal") -> Normal | R4: =COUNTIF(G:G,G4) -> 29 | S4: =AVERAGE(O2:O251) -> 916.76988 | T4: =LEFT(E4,1)&MID(E4,FIND(" ",E4)+1,1) -> KS
A5: TRX0043 | B5: 45400 | C5: =TEXT(B5,"mmmm") -> April | D5: CUST046 | E5: Kathleen Bennett | F5: P005 | G5: Blender | H5: Appliances | I5: 3 | J5: 59.99 | K5: Cash | L5: North | M5: Premium | N5: 45114 | O5: 179.97 | P5: =DATEDIF(O5,TODAY(),"Y") -> 125 | Q5: =IF(O5>2000,"High Value","Normal") -> Normal | R5: =COUNTIF(G:G,G5) -> 29 | S5: transaction | T5: =LEFT(E5,1)&MID(E5,FIND(" ",E5)+1,1) -> KB
A6: TRX0212 | B6: 45400 | C6: =TEXT(B6,"mmmm") -> April | D6: CUST003 | E6: Michael Brown | F6: P008 | G6: Bookshelf | H6: Furniture | I6: 5 | J6: 149.99 | K6: Credit Card | L6: North | M6: Premium | N6: 45295 | O6: 749.95 | P6: =DATEDIF(O6,TODAY(),"Y") -> 124 | Q6: =IF(O6>2000,"High Value","Normal") -> Normal | R6: =COUNTIF(G:G,G6) -> 35 | S6: =COUNTA(A:A)-1 -> 250 | T6: =LEFT(E6,1)&MID(E6,FIND(" ",E6)+1,1) -> MB
A7: TRX0092 | B7: 45403 | C7: =TEXT(B7,"mmmm") -> April | D7: CUST024 | E7: Dorothy Nelson | F7: P005 | G7: Blender | H7: Appliances | I7: 2 | J7: 59.99 | K7: Cash | L7: West | M7: Standard | N7: 44746 | O7: 119.98 | P7: =DATEDIF(O7,TODAY(),"Y") -> 126 | Q7: =IF(O7>2000,"High Value","Normal") -> Normal | R7: =COUNTIF(G:G,G7) -> 29 | T7: =LEFT(E7,1)&MID(E7,FIND(" ",E7)+1,1) -> DN
A8: TRX0193 | B8: 45403 | C8: =TEXT(B8,"mmmm") -> April | D8: CUST024 | E8: Dorothy Nelson | F8: P003 | G8: Headphones | H8: Electronics | I8: 0 | J8: 149.99 | K8: Credit Card | L8: Central | M8: Standard | N8: 44418 | O8: 749.95 | P8: =DATEDIF(O8,TODAY(),"Y") -> 124 | Q8: =IF(O8>2000,"High Value","Normal") -> Normal | R8: =COUNTIF(G:G,G8) -> 16 | T8: =LEFT(E8,1)&MID(E8,FIND(" ",E8)+1,1) -> DN
A9: TRX0240 | B9: 45403 | C9: =TEXT(B9,"mmmm") -> April | D9: CUST017 | E9: Charles Allen | F9: P005 | G9: Blender | H9: Appliances | I9: 3 | J9: 59.99 | K9: Debit Card | L9: South | M9: Basic | N9: 45007 | O9: 179.97 | P9: =DATEDIF(O9,TODAY(),"Y") -> 125 | Q9: =IF(O9>2000,"High Value","Normal") -> Normal | R9: =COUNTIF(G:G,G9) -> 29 | T9: =LEFT(E9,1)&MID(E9,FIND(" ",E9)+1,1) -> CA
A10: TRX0135 | B10: 45405 | C10: =TEXT(B10,"mmmm") -> April | D10: CUST009 | E10: Robert Thomas | F10: P001 | G10: Laptop | H10: Electronics | I10: 3 | J10: 899.99 | K10: PayPal | L10: East | M10: Standard | N10: 45299 | O10: 2699.97 | P10: =DATEDIF(O10,TODAY(),"Y") -> 118 | Q10: =IF(O10>2000,"High Value","Normal") -> High Value | R10: =COUNTIF(G:G,G10) -> 24 | T10: =LEFT(E10,1)&MID(E10,FIND(" ",E10)+1,1) -> RT
A11: TRX0185 | B11: 45408 | C11: =TEXT(B11,"mmmm") -> April | D11: CUST026 | E11: Karen Hill | F11: P005 | G11: Blender | H11: Appliances | I11: 3 | J11: 59.99 | K11: Cash | L11: West | M11: Premium | N11: 45207 | O11: 179.97 | P11: =DATEDIF(O11,TODAY(),"Y") -> 125 | Q11: =IF(O11>2000,"High Value","Normal") -> Normal | R11: =COUNTIF(G:G,G11) -> 29 | T11: =LEFT(E11,1)&MID(E11,FIND(" ",E11)+1,1) -> KH
A12: TRX0138 | B12: 45408 | C12: =TEXT(B12,"mmmm") -> April | D12: CUST022 | E12: Susan Green | F12: P008 | G12: Bookshelf | H12: Furniture | I12: 1 | J12: 149.99 | K12: Credit Card | L12: West | M12: Standard | N12: 45103 | O12: 149.99 | P12: =DATEDIF(O12,TODAY(),"Y") -> 125 | Q12: =IF(O12>2000,"High Value","Normal") -> Normal | R12: =COUNTIF(G:G,G12) -> 35 | T12: =LEFT(E12,1)&MID(E12,FIND(" ",E12)+1,1) -> SG
A13: TRX0209 | B13: 45408 | C13: =TEXT(B13,"mmmm") -> April | D13: CUST046 | E13: Kathleen Bennett | F13: P008 | G13: Bookshelf | H13: Furniture | I13: 5 | J13: 149.99 | K13: Debit Card | L13: North | M13: Basic | N13: 44830 | O13: 749.95 | P13: =DATEDIF(O13,TODAY(),"Y") -> 124 | Q13: =IF(O13>2000,"High Value","Normal") -> Normal | R13: =COUNTIF(G:G,G13) -> 35 | T13: =LEFT(E13,1)&MID(E13,FIND(" ",E13)+1,1) -> KB
A14: TRX0246 | B14: 45408 | C14: =TEXT(B14,"mmmm") -> April | D14: CUST041 | E14: Peter Richardson | F14: P008 | G14: Bookshelf | H14: Furniture | I14: 3 | J14: 149.99 | K14: Cash | L14: North | M14: Premium | N14: 44806 | O14: 449.97 | P14: =DATEDIF(O14,TODAY(),"Y") -> 125 | Q14: =IF(O14>2000,"High Value","Normal") -> Normal | R14: =COUNTIF(G:G,G14) -> 35 | T14: =LEFT(E14,1)&MID(E14,FIND(" ",E14)+1,1) -> PR
A15: TRX0067 | B15: 45409 | C15: =TEXT(B15,"mmmm") -> April | D15: CUST043 | E15: Dennis Gray | F15: P005 | G15: Blender | H15: Appliances | I15: 3 | J15: 59.99 | K15: Credit Card | L15: North | M15: Standard | N15: 45351 | O15: 179.97 | P15: =DATEDIF(O15,TODAY(),"Y") -> 125 | Q15: =IF(O15>2000,"High Value","Normal") -> Normal | R15: =COUNTIF(G:G,G15) -> 29 | T15: =LEFT(E15,1)&MID(E15,FIND(" ",E15)+1,1) -> DG
A16: TRX0191 | B16: 45409 | C16: =TEXT(B16,"mmmm") -> April | D16: CUST038 | E16: Michelle Rogers | F16: P002 | G16: Smartphone | H16: Electronics | I16: 3 | J16: 699.99 | K16: Credit Card | L16: West | M16: Basic | N16: 44577 | O16: 2099.97 | P16: =DATEDIF(O16,TODAY(),"Y") -> 120 | Q16: =IF(O16>2000,"High Value","Normal") -> High Value | R16: =COUNTIF(G:G,G16) -> 31 | T16: =LEFT(E16,1)&MID(E16,FIND(" ",E16)+1,1) -> MR
A17: TRX0230 | B17: 45409 | C17: =TEXT(B17,"mmmm") -> April | D17: CUST027 | E17: George Adams | F17: P001 | G17: Laptop | H17: Electronics | I17: 1 | J17: 899.99 | K17: Debit Card | L17: North | M17: Standard | N17: 44920 | O17: 899.99 | P17: =DATEDIF(O17,TODAY(),"Y") -> 123 | Q17: =IF(O17>2000,"High Value","Normal") -> Normal | R17: =COUNTIF(G:G,G17) -> 24 | T17: =LEFT(E17,1)&MID(E17,FIND(" ",E17)+1,1) -> GA
A18: TRX0049 | B18: 45410 | C18: =TEXT(B18,"mmmm") -> April | D18: CUST025 | E18: Mark Carter | F18: P008 | G18: Bookshelf | H18: Furniture | I18: 4 | J18: 149.99 | K18: Debit Card | L18: North | M18: Premium | N18: 45374 | O18: 599.96 | P18: =DATEDIF(O18,TODAY(),"Y") -> 124 | Q18: =IF(O18>2000,"High Value","Normal") -> Normal | R18: =COUNTIF(G:G,G18) -> 35 | T18: =LEFT(E18,1)&MID(E18,FIND(" ",E18)+1,1) -> MC
... A74: TRX0131 | B74: 45491 | C74: =TEXT(B74,"mmmm") -> July | D74: CUST026 | E74: Karen Hill | F74: P006 | G74: Office Chair | H74: Furniture | I74: 3 | J74: 199.99 | K74: Cash | L74: North | M74: Premium | N74: 45254 | O74: 599.97 | P74: =DATEDIF(O74,TODAY(),"Y") -> 124 | Q74: =IF(O74>2000,"High Value","Normal") -> Normal | R74: =COUNTIF(G:G,G74) -> 15 | T74: =LEFT(E74,1)&MID(E74,FIND(" ",E74)+1,1) -> KH
A75: TRX0162 | B75: 45496 | C75: =TEXT(B75,"mmmm") -> July | D75: CUST040 | E75: Sharon Butler | F75: P001 | G75: Laptop | H75: Electronics | I75: x | J75: 899.99 | K75: Cash | L75: Central | M75: Standard | N75: 45179 | O75: 899.99 | P75: =DATEDIF(O75,TODAY(),"Y") -> 123 | Q75: =IF(O75>2000,"High Value","Normal") -> Normal | R75: =COUNTIF(G:G,G75) -> 24 | T75: =LEFT(E75,1)&MID(E75,FIND(" ",E75)+1,1) -> SB
A76: TRX0244 | B76: 45497 | C76: =TEXT(B76,"mmmm") -> July | D76: CUST013 | E76: Joseph Jackson | F76: P001 | G76: Laptop | H76: Electronics | I76: 5 | J76: 899.99 | K76: Debit Card | L76: South | M76: Standard | N76: 44899 | O76: 4499.95 | P76: =DATEDIF(O76,TODAY(),"Y") -> 114 | Q76: =IF(O76>2000,"High Value","Normal") -> High Value | R76: =COUNTIF(G:G,G76) -> 24 | T76: =LEFT(E76,1)&MID(E76,FIND(" ",E76)+1,1) -> JJ
A77: TRX0006 | B77: 45498 | C77: =TEXT(B77,"mmmm") -> July | D77: CUST007 | E77: David Martinez | F77: P005 | G77: Blender | H77: Appliances | I77: 2 | J77: 59.99 | K77: Cash | L77: North | M77: Standard | N77: 45152 | O77: 119.98 | P77: =DATEDIF(O77,TODAY(),"Y") -> 126 | Q77: =IF(O77>2000,"High Value","Normal") -> Normal | R77: =COUNTIF(G:G,G77) -> 29 | T77: =LEFT(E77,1)&MID(E77,FIND(" ",E77)+1,1) -> DM
A78: TRX0215 | B78: 45498 | C78: =TEXT(B78,"mmmm") -> July | D78: CUST047 | E78: Gerald Murphy | F78: P009 | G78: Monitor | H78: Electronics | I78: 4 | J78: 249.99 | K78: Debit Card | L78: Central | M78: Standard | N78: 45127 | O78: 999.96 | P78: =DATEDIF(O78,TODAY(),"Y") -> 123 | Q78: =IF(O78>2000,"High Value","Normal") -> Normal | R78: =COUNTIF(G:G,G78) -> 26 | T78: =LEFT(E78,1)&MID(E78,FIND(" ",E78)+1,1) -> GM
A79: TRX0080 | B79: 45500 | C79: =TEXT(B79,"mmmm") -> July | D79: CUST018 | E79: Barbara Young | F79: P009 | G79: Monitor | H79: Electronics | I79: 2 | J79: 249.99 | K79: Cash | L79: North | M79: Premium | N79: 45164 | O79: 499.98 | P79: =DATEDIF(O79,TODAY(),"Y") -> 124 | Q79: =IF(O79>2000,"High Value","Normal") -> Normal | R79: =COUNTIF(G:G,G79) -> 26 | T79: =LEFT(E79,1)&MID(E79,FIND(" ",E79)+1,1) -> BY
A80: TRX0228 | B80: 45500 | C80: =TEXT(B80,"mmmm") -> July | D80: CUST019 | E80: Daniel King | F80: P007 | G80: Desk | H80: Furniture | I80: 1 | J80: 299.99 | K80: Cash | L80: South | M80: Basic | N80: 44982 | O80: 299.99 | P80: =DATEDIF(O80,TODAY(),"Y") -> 125 | Q80: =IF(O80>2000,"High Value","Normal") -> Normal | R80: =COUNTIF(G:G,G80) -> 26 | T80: =LEFT(E80,1)&MID(E80,FIND(" ",E80)+1,1) -> DK
A81: TRX0157 | B81: 45501 | C81: =TEXT(B81,"mmmm") -> July | D81: CUST025 | E81: Mark Carter | F81: P010 | G81: Keyboard | H81: Electronics | I81: 2 | J81: 89.99 | K81: PayPal | L81: South | M81: Basic | N81: 44976 | O81: 179.98 | P81: =DATEDIF(O81,TODAY(),"Y") -> 125 | Q81: =IF(O81>2000,"High Value","Normal") -> Normal | R81: =COUNTIF(G:G,G81) -> 34 | T81: =LEFT(E81,1)&MID(E81,FIND(" ",E81)+1,1) -> MC
A82: TRX0002 | B82: 45501 | C82: =TEXT(B82,"mmmm") -> July | D82: CUST019 | E82: Daniel King | F82: P007 | G82: Desk | H82: Furniture | I82: 3 | J82: 299.99 | K82: Cash | L82: Central | M82: Basic | N82: 44732 | O82: 899.97 | P82: =DATEDIF(O82,TODAY(),"Y") -> 123 | Q82: =IF(O82>2000,"High Value","Normal") -> Normal | R82: =COUNTIF(G:G,G82) -> 26 | T82: =LEFT(E82,1)&MID(E82,FIND(" ",E82)+1,1) -> DK
A83: TRX0217 | B83: 45503 | C83: =TEXT(B83,"mmmm") -> July | D83: CUST025 | E83: Mark Carter | F83: P002 | G83: Smartphone | H83: Electronics | I83: 2 | J83: 699.99 | K83: Credit Card | L83: North | M83: Premium | N83: 44999 | O83: 1399.98 | P83: =DATEDIF(O83,TODAY(),"Y") -> 122 | Q83: =IF(O83>2000,"High Value","Normal") -> Normal | R83: =COUNTIF(G:G,G83) -> 31 | T83: =LEFT(E83,1)&MID(E83,FIND(" ",E83)+1,1) -> MC
A84: TRX0249 | B84: 45504 | C84: =TEXT(B84,"mmmm") -> July | D84: CUST030 | E84: Helen Roberts | F84: P001 | G84: Laptop | H84: Electronics | I84: 4 | J84: 899.99 | K84: Debit Card | L84: South | M84: Standard | N84: 44523 | O84: 3599.96 | P84: =DATEDIF(O84,TODAY(),"Y") -> 116 | Q84: =IF(O84>2000,"High Value","Normal") -> High Value | R84: =COUNTIF(G:G,G84) -> 24 | T84: =LEFT(E84,1)&MID(E84,FIND(" ",E84)+1,1) -> HR
A85: TRX0065 | B85: 45509 | C85: =TEXT(B85,"mmmm") -> August | D85: CUST016 | E85: Elizabeth Hall | F85: P008 | G85: Bookshelf | H85: Furniture | I85: 2 | J85: 149.99 | K85: Credit Card | L85: West | M85: Basic | N85: 44542 | O85: 299.98 | P85: =DATEDIF(O85,TODAY(),"Y") -> 125 | Q85: =IF(O85>2000,"High Value","Normal") -> Normal | R85: =COUNTIF(G:G,G85) -> 35 | T85: =LEFT(E85,1)&MID(E85,FIND(" ",E85)+1,1) -> EH
A86: TRX0176 | B86: 45510 | C86: =TEXT(B86,"mmmm") -> August | D86: CUST044 | E86: Cynthia Price | F86: P008 | G86: Bookshelf | H86: Furniture | I86: 2 | J86: 149.99 | K86: Debit Card | L86: East | M86: Standard | N86: 44667 | O86: 299.98 | P86: =DATEDIF(O86,TODAY(),"Y") -> 125 | Q86: =IF(O86>2000,"High Value","Normal") -> Normal | R86: =COUNTIF(G:G,G86) -> 35 | T86: =LEFT(E86,1)&MID(E86,FIND(" ",E86)+1,1) -> CP
A87: TRX0101 | B87: 45513 | C87: =TEXT(B87,"mmmm") -> August | D87: CUST010 | E87: Maria Garcia | F87: P010 | G87: Keyboard | H87: Electronics | I87: 1 | J87: 89.99 | K87: Credit Card | L87: North | M87: Standard | N87: 45393 | O87: 89.99 | P87: =DATEDIF(O87,TODAY(),"Y") -> 126 | Q87: =IF(O87>2000,"High Value","Normal") -> Normal | R87: =COUNTIF(G:G,G87) -> 34 | T87: =LEFT(E87,1)&MID(E87,FIND(" ",E87)+1,1) -> MG
... A251: TRX0064 | B251: 45758 | C251: =TEXT(B251,"mmmm") -> April | D251: CUST031 | E251: Steven Turner | F251: P010 | G251: Keyboard | H251: Electronics | I251: 3 | J251: 89.99 | K251: Debit Card | L251: North | M251: Premium | N251: 44878 | O251: 269.97 | P251: =DATEDIF(O251,TODAY(),"Y") -> 125 | Q251: =IF(O251>2000,"High Value","Normal") -> Normal | R251: =COUNTIF(G:G,G251) -> 34 | T251: =LEFT(E251,1)&MID(E251,FIND(" ",E251)+1,1) -> ST

Sheet SALES ANALYSIS
A1: Electronics only using filter
A2: {=_xlfn._xlws.FILTER('RAW DATA'!A2:O500,'RAW DATA'!H2:H500="Electronics")} -> TRX0155 | B2: 45393 | C2: April | D2: CUST023 | E2: Paul Baker | F2: P009 | G2: Monitor | H2: Electronics | I2: 5 | J2: 274.98 | K2: Cash | L2: Central | M2: Basic | N2: 44425 | O2: 749.97
A3: TRX0023 | B3: 45396 | C3: April | D3: CUST013 | E3: Joseph Jackson | F3: P009 | G3: Monitor | H3: Electronics | I3: 0 | J3: 249.99 | K3: Credit Card | L3: Central | M3: Premium | N3: 44575 | O3: 749.97
A4: TRX0193 | B4: 45403 | C4: April | D4: CUST024 | E4: Dorothy Nelson | F4: P003 | G4: Headphones | H4: Electronics | I4: 0 | J4: 149.99 | K4: Credit Card | L4: Central | M4: Standard | N4: 44418 | O4: 749.95
A5: TRX0135 | B5: 45405 | C5: April | D5: CUST009 | E5: Robert Thomas | F5: P001 | G5: Laptop | H5: Electronics | I5: 3 | J5: 899.99 | K5: PayPal | L5: East | M5: Standard | N5: 45299 | O5: 2699.97
A6: TRX0191 | B6: 45409 | C6: April | D6: CUST038 | E6: Michelle Rogers | F6: P002 | G6: Smartphone | H6: Electronics | I6: 3 | J6: 699.99 | K6: Credit Card | L6: West | M6: Basic | N6: 44577 | O6: 2099.97
A7: TRX0230 | B7: 45409 | C7: April | D7: CUST027 | E7: George Adams | F7: P001 | G7: Laptop | H7: Electronics | I7: 1 | J7: 899.99 | K7: Debit Card | L7: North | M7: Standard | N7: 44920 | O7: 899.99
A8: TRX0134 | B8: 45410 | C8: April | D8: CUST010 | E8: Maria Garcia | F8: P002 | G8: Smartphone | H8: Electronics | I8: 2 | J8: 699.99 | K8: Cash | L8: North | M8: Basic | N8: 44781 | O8: 1399.98
A9: TRX0122 | B9: 45410 | C9: April | D9: CUST025 | E9: Mark Carter | F9: P001 | G9: Laptop | H9: Electronics | I9: 4 | J9: 899.99 | K9: Credit Card | L9: West | M9: Standard | N9: 45327 | O9: 3599.96
A10: TRX0222 | B10: 45410 | C10: April | D10: CUST048 | E10: Virginia Sanders | F10: P009 | G10: Monitor | H10: Electronics | I10: 3 | J10: 249.99 | K10: Credit Card | L10: North | M10: Premium | N10: 45224 | O10: 749.97
A11: TRX0231 | B11: 45412 | C11: April | D11: CUST018 | E11: Barbara Young | F11: P002 | G11: Smartphone | H11: Electronics | I11: 5 | J11: 699.99 | K11: Cash | L11: West | M11: Basic | N11: 45167 | O11: 3499.95
A12: TRX0239 | B12: 45413 | C12: May | D12: CUST012 | E12: Patricia Moore | F12: P002 | G12: Smartphone | H12: Electronics | I12: 4 | J12: 699.99 | K12: Cash | L12: East | M12: Standard | N12: 44409 | O12: 2799.96
A13: TRX0204 | B13: 45415 | C13: May | D13: CUST044 | E13: Cynthia Price | F13: P009 | G13: Monitor | H13: Electronics | I13: 4 | J13: 249.99 | K13: PayPal | L13: North | M13: Standard | N13: 44468 | O13: 999.96
A14: TRX0071 | B14: 45422 | C14: May | D14: CUST036 | E14: Nancy Collins | F14: P009 | G14: Monitor | H14: Electronics | I14: 0 | J14: 249.99 | K14: Credit Card | L14: West | M14: Standard | N14: 44525 | O14: 1249.95
... A36: TRX0018 | B36: 45484 | C36: July | D36: CUST013 | E36: Joseph Jackson | F36: P003 | G36: Headphones | H36: Electronics | I36: 1 | J36: 149.99 | K36: Cash | L36: Central | M36: Standard | N36: 44909 | O36: 149.99
A37: TRX0162 | B37: 45496 | C37: July | D37: CUST040 | E37: Sharon Butler | F37: P001 | G37: Laptop | H37: Electronics | I37: x | J37: 899.99 | K37: Cash | L37: Central | M37: Standard | N37: 45179 | O37: 899.99
A38: TRX0244 | B38: 45497 | C38: July | D38: CUST013 | E38: Joseph Jackson | F38: P001 | G38: Laptop | H38: Electronics | I38: 5 | J38: 899.99 | K38: Debit Card | L38: South | M38: Standard | N38: 44899 | O38: 4499.95
A39: TRX0215 | B39: 45498 | C39: July | D39: CUST047 | E39: Gerald Murphy | F39: P009 | G39: Monitor | H39: Electronics | I39: 4 | J39: 249.99 | K39: Debit Card | L39: Central | M39: Standard | N39: 45127 | O39: 999.96
A40: TRX0080 | B40: 45500 | C40: July | D40: CUST018 | E40: Barbara Young | F40: P009 | G40: Monitor | H40: Electronics | I40: 2 | J40: 249.99 | K40: Cash | L40: North | M40: Premium | N40: 45164 | O40: 499.98
A41: TRX0157 | B41: 45501 | C41: July | D41: CUST025 | E41: Mark Carter | F41: P010 | G41: Keyboard | H41: Electronics | I41: 2 | J41: 89.99 | K41: PayPal | L41: South | M41: Basic | N41: 44976 | O41: 179.98
A42: TRX0217 | B42: 45503 | C42: July | D42: CUST025 | E42: Mark Carter | F42: P002 | G42: Smartphone | H42: Electronics | I42: 2 | J42: 699.99 | K42: Credit Card | L42: North | M42: Premium | N42: 44999 | O42: 1399.98
A43: TRX0249 | B43: 45504 | C43: July | D43: CUST030 | E43: Helen Roberts | F43: P001 | G43: Laptop | H43: Electronics | I43: 4 | J43: 899.99 | K43: Debit Card | L43: South | M43: Standard | N43: 44523 | O43: 3599.96
A44: TRX0101 | B44: 45513 | C44: August | D44: CUST010 | E44: Maria Garcia | F44: P010 | G44: Keyboard | H44: Electronics | I44: 1 | J44: 89.99 | K44: Credit Card | L44: North | M44: Standard | N44: 45393 | O44: 89.99
A45: TRX0020 | B45: 45517 | C45: August | D45: CUST007 | E45: David Martinez | F45: P003 | G45: Headphones | H45: Electronics | I45: 4 | J45: 149.99 | K45: Debit Card | L45: South | M45: Premium | N45: 44820 | O45: 599.96
A46: TRX0075 | B46: 45517 | C46: August | D46: CUST020 | E46: Margaret Wright | F46: P009 | G46: Monitor | H46: Electronics | I46: 5 | J46: 249.99 | K46: PayPal | L46: East | M46: Premium | N46: 44782 | O46: 1249.95
A47: TRX0098 | B47: 45517 | C47: August | D47: CUST026 | E47: Karen Hill | F47: P009 | G47: Monitor | H47: Electronics | I47: 3 | J47: 249.99 | K47: PayPal | L47: North | M47: Premium | N47: 44465 | O47: 749.97
A48: TRX0140 | B48: 45522 | C48: August | D48: CUST025 | E48: Mark Carter | F48: P010 | G48: Keyboard | H48: Electronics | I48: 2 | J48: 89.99 | K48: Cash | L48: East | M48: Premium | N48: 44972 | O48: 179.98
A49: TRX0132 | B49: 45523 | C49: August | D49: CUST047 | E49: Gerald Murphy | F49: P001 | G49: Laptop | H49: Electronics | I49: 5 | J49: 899.99 | K49: Debit Card | L49: East | M49: Basic | N49: 44526 | O49: 4499.95
... A132: TRX0064 | B132: 45758 | C132: April | D132: CUST031 | E132: Steven Turner | F132: P010 | G132: Keyboard | H132: Electronics | I132: 3 | J132: 89.99 | K132: Debit Card | L132: North | M132: Premium | N132: 44878 | O132: 269.97
A133: Sales above 2000
A134: {=_xlfn._xlws.FILTER('RAW DATA'!A2:O500,'RAW DATA'!O2:O500>2000)} -> TRX0135 | B134: 45405 | C134: April | D134: CUST009 | E134: Robert Thomas | F134: P001 | G134: Laptop | H134: Electronics | I134: 3 | J134: 899.99 | K134: PayPal | L134: East | M134: Standard | N134: 45299 | O134: 2699.97
A135: TRX0191 | B135: 45409 | C135: April | D135: CUST038 | E135: Michelle Rogers | F135: P002 | G135: Smartphone | H135: Electronics | I135: 3 | J135: 699.99 | K135: Credit Card | L135: West | M135: Basic | N135: 44577 | O135: 2099.97
A136: TRX0122 | B136: 45410 | C136: April | D136: CUST025 | E136: Mark Carter | F136: P001 | G136: Laptop | H136: Electronics | I136: 4 | J136: 899.99 | K136: Credit Card | L136: West | M136: Standard | N136: 45327 | O136: 3599.96
A137: TRX0231 | B137: 45412 | C137: April | D137: CUST018 | E137: Barbara Young | F137: P002 | G137: Smartphone | H137: Electronics | I137: 5 | J137: 699.99 | K137: Cash | L137: West | M137: Basic | N137: 45167 | O137: 3499.95
A138: TRX0239 | B138: 45413 | C138: May | D138: CUST012 | E138: Patricia Moore | F138: P002 | G138: Smartphone | H138: Electronics | I138: 4 | J138: 699.99 | K138: Cash | L138: East | M138: Standard | N138: 44409 | O138: 2799.96
A139: TRX0015 | B139: 45440 | C139: May | D139: CUST008 | E139: Jennifer Taylor | F139: P002 | G139: Smartphone | H139: Electronics | I139: 0 | J139: 699.99 | K139: PayPal | L139: West | M139: Standard | N139: 44407 | O139: 3499.95
A140: TRX0154 | B140: 45459 | C140: June | D140: CUST023 | E140: Paul Baker | F140: P001 | G140: Laptop | H140: Electronics | I140: 5 | J140: 899.99 | K140: Credit Card | L140: South | M140: Standard | N140: 44974 | O140: 4499.95
A141: TRX0044 | B141: 45459 | C141: June | D141: CUST029 | E141: Edward Mitchell | F141: P001 | G141: Laptop | H141: Electronics | I141: 5 | J141: 899.99 | K141: PayPal | L141: East | M141: Premium | N141: 45278 | O141: 4499.95
A142: TRX0184 | B142: 45471 | C142: June | D142: CUST046 | E142: Kathleen Bennett | F142: P002 | G142: Smartphone | H142: Electronics | I142: 0 | J142: 699.99 | K142: Credit Card | L142: East | M142: Premium | N142: 45102 | O142: 2099.97
A143: TRX0104 | B143: 45471 | C143: June | D143: CUST012 | E143: Patricia Moore | F143: P001 | G143: Laptop | H143: Electronics | I143: 0 | J143: 899.99 | K143: Credit Card | L143: East | M143: Premium | N143: 44993 | O143: 3599.96
...

Sheet REGRESSION ANALYSIS
A1: SUMMARY OUTPUT
A3: Regression Statistics
A4: Multiple R | B4: 0.45510124
A5: R Square | B5: 0.20711714
A6: Adjusted R Square | B6: 0.20392003
A7: Standard Error | B7: 921.18887
A8: Observations | B8: 250
A10: ANOVA
B11: df | C11: SS | D11: MS | E11: F | F11: Significance F
A12: Regression | B12: 1 | C12: 54973837 | D12: 54973837 | E12: 64.782646 | F12: 3.4807531e-14
A13: Residual | B13: 248 | C13: 2.1045005e+08 | D13: 848588.93
A14: Total | B14: 249 | C14: 2.6542389e+08
B16: Coefficients | C16: Standard Error | D16: t Stat | E16: P-value | F16: Lower 95% | G16: Upper 95% | H16: Lower 95.0% | I16: Upper 95.0%
A17: Intercept | B17: -140.07236 | C17: 143.65 | D17: -0.97509474 | E17: 0.33046342 | F17: -423.00191 | G17: 142.85719 | H17: -423.00191 | I17: 142.85719
A18: Quantity | B18: 349.94776 | C18: 43.478433 | D18: 8.0487668 | E18: 3.4807531e-14 | F18: 264.3137 | G18: 435.58182 | H18: 264.3137 | I18: 435.58182

Sheet PRODUCTS & CUSTOMERS
A1: high value customer | C1: Product_Name | D1: frequently purchased product | F1: Customer_Name | G1: Repeating names | I1: Customer_Name | J1: Customer_Segment | K1: compare list
A2: =IF(SUMIFS('RAW DATA'!O:O,'RAW DATA'!D:D,'RAW DATA'!D2)>5000,"High Value","Normal") -> High Value | C2: Monitor | D2: =COUNTIF(C:C,C2) -> 26 | F2: Paul Baker | G2: =COUNTIF(F:F,F2) -> 8 | I2: Paul Baker | J2: Basic | K2: =IF(COUNTIF($J$2:$J$251,I2)>0,"Match","Non Match") -> Non Match
A3: =IF(SUMIFS('RAW DATA'!O:O,'RAW DATA'!D:D,'RAW DATA'!D3)>5000,"High Value","Normal") -> High Value | C3: Monitor | D3: =COUNTIF(C:C,C3) -> 26 | F3: Joseph Jackson | G3: =COUNTIF(F:F,F3) -> 5 | I3: Joseph Jackson | J3: Premium | K3: =IF(COUNTIF(J3:J252,I3)>0,"Match","Non Match") -> Non Match
A4: =IF(SUMIFS('RAW DATA'!O:O,'RAW DATA'!D:D,'RAW DATA'!D4)>5000,"High Value","Normal") -> Normal | C4: Blender | D4: =COUNTIF(C:C,C4) -> 29 | F4: Kevin Scott | G4: =COUNTIF(F:F,F4) -> 6 | I4: Kevin Scott | J4: Standard | K4: =IF(COUNTIF(J4:J253,I4)>0,"Match","Non Match") -> Non Match
A5: =IF(SUMIFS('RAW DATA'!O:O,'RAW DATA'!D:D,'RAW DATA'!D5)>5000,"High Value","Normal") -> Normal | C5: Blender | D5: =COUNTIF(C:C,C5) -> 29 | F5: Kathleen Bennett | G5: =COUNTIF(F:F,F5) -> 6 | I5: Kathleen Bennett | J5: Premium | K5: =IF(COUNTIF(J5:J254,I5)>0,"Match","Non Match") -> Non Match
A6: =IF(SUMIFS('RAW DATA'!O:O,'RAW DATA'!D:D,'RAW DATA'!D6)>5000,"High Value","Normal") -> High Value | C6: Bookshelf | D6: =COUNTIF(C:C,C6) -> 35 | F6: Michael Brown | G6: =COUNTIF(F:F,F6) -> 9 | I6: Michael Brown | J6: Premium | K6: =IF(COUNTIF(J6:J255,I6)>0,"Match","Non Match") -> Non Match
A7: =IF(SUMIFS('RAW DATA'!O:O,'RAW DATA'!D:D,'RAW DATA'!D7)>5000,"High Value","Normal") -> High Value | C7: Blender | D7: =COUNTIF(C:C,C7) -> 29 | F7: Dorothy Nelson | G7: =COUNTIF(F:F,F7) -> 6 | I7: Dorothy Nelson | J7: Standard | K7: =IF(COUNTIF(J7:J256,I7)>0,"Match","Non Match") -> Non Match
A8: =IF(SUMIFS('RAW DATA'!O:O,'RAW DATA'!D:D,'RAW DATA'!D8)>5000,"High Value","Normal") -> High Value | C8: Headphones | D8: =COUNTIF(C:C,C8) -> 16 | F8: Dorothy Nelson | G8: =COUNTIF(F:F,F8) -> 6 | I8: Dorothy Nelson | J8: Standard | K8: =IF(COUNTIF(J8:J257,I8)>0,"Match","Non Match") -> Non Match
A9: =IF(SUMIFS('RAW DATA'!O:O,'RAW DATA'!D:D,'RAW DATA'!D9)>5000,"High Value","Normal") -> High Value | C9: Blender | D9: =COUNTIF(C:C,C9) -> 29 | F9: Charles Allen | G9: =COUNTIF(F:F,F9) -> 9 | I9: Charles Allen | J9: Basic | K9: =IF(COUNTIF(J9:J258,I9)>0,"Match","Non Match") -> Non Match
A10: =IF(SUMIFS('RAW DATA'!O:O,'RAW DATA'!D:D,'RAW DATA'!D10)>5000,"High Value","Normal") -> Normal | C10: Laptop | D10: =COUNTIF(C:C,C10) -> 24 | F10: Robert Thomas | G10: =COUNTIF(F:F,F10) -> 5 | I10: Robert Thomas | J10: Standard | K10: =IF(COUNTIF(J10:J259,I10)>0,"Match","Non Match") -> Non Match
A11: =IF(SUMIFS('RAW DATA'!O:O,'RAW DATA'!D:D,'RAW DATA'!D11)>5000,"High Value","Normal") -> High Value | C11: Blender | D11: =COUNTIF(C:C,C11) -> 29 | F11: Karen Hill | G11: =COUNTIF(F:F,F11) -> 8 | I11: Karen Hill | J11: Premium | K11: =IF(COUNTIF(J11:J260,I11)>0,"Match","Non Match") -> Non Match
A12: =IF(SUMIFS('RAW DATA'!O:O,'RAW DATA'!D:D,'RAW DATA'!D12)>5000,"High Value","Normal") -> Normal | C12: Bookshelf | D12: =COUNTIF(C:C,C12) -> 35 | F12: Susan Green | G12: =COUNTIF(F:F,F12) -> 4 | I12: Susan Green | J12: Standard | K12: =IF(COUNTIF(J12:J261,I12)>0,"Match","Non Match") -> Non Match
A13: =IF(SUMIFS('RAW DATA'!O:O,'RAW DATA'!D:D,'RAW DATA'!D13)>5000,"High Value","Normal") -> Normal | C13: Bookshelf | D13: =COUNTIF(C:C,C13) -> 35 | F13: Kathleen Bennett | G13: =COUNTIF(F:F,F13) -> 6 | I13: Kathleen Bennett | J13: Basic | K13: =IF(COUNTIF(J13:J262,I13)>0,"Match","Non Match") -> Non Match
A14: =IF(SUMIFS('RAW DATA'!O:O,'RAW DATA'!D:D,'RAW DATA'!D14)>5000,"High Value","Normal") -> High Value | C14: Bookshelf | D14: =COUNTIF(C:C,C14) -> 35 | F14: Peter Richardson | G14: =COUNTIF(F:F,F14) -> 5 | I14: Peter Richardson | J14: Premium | K14: =IF(COUNTIF(J14:J263,I14)>0,"Match","Non Match") -> Non Match
... A251: =IF(SUMIFS('RAW DATA'!O:O,'RAW DATA'!D:D,'RAW DATA'!D251)>5000,"High Value","Normal") -> Normal | C251: Keyboard | D251: =COUNTIF(C:C,C251) -> 34 | F251: Steven Turner | G251: =COUNTIF(F:F,F251) -> 6 | I251: Steven Turner | J251: Premium | K251: =IF(COUNTIF(J251:J500,I251)>0,"Match","Non Match") -> Non Match

Sheet PIVOT TABLE
A4: Row Labels | B4: Sum of Total_Amount | D4: Row Labels | E4: Sum of Total_Amount
A5: Central | B5: 41288.34 | D5: Appliances | E5: 8338.74
A6: East | B6: 59288.39 | D6: Electronics | E6: 171756.05
A7: North | B7: 50808.31 | D7: Furniture | E7: 49097.68
A8: South | B8: 36398.75 | D8: Grand Total | E8: 229192.47
A9: West | B9: 41408.68
A10: Grand Total | B10: 229192.47
A13: Row Labels | B13: Sum of Total_Amount | D13: Row Labels | E13: Sum of Total_Amount
A14: Cash | B14: 57427.79 | D14: January | E14: 25799.15
A15: Credit Card | B15: 61447.96 | D15: February | E15: 16069.38
A16: Debit Card | B16: 52118.31 | D16: March | E16: 19899.38
A17: PayPal | B17: 58198.41 | D17: April | E17: 27899.16
A18: Grand Total | B18: 229192.47 | D18: May | E18: 17039.35
D19: June | E19: 19299.45
D20: July | E20: 18479.4
D21: August | E21: 15759.43
D22: September | E22: 12989.51
D23: October | E23: 20609.52
D24: November | E24: 12309.44
D25: December | E25: 23039.3
D26: Grand Total | E26: 229192.47
